Workbook

Sheet Catalyst details
A1: Cathode Details | D1: Anode Details
A2: Preparation Date | B2: 46059 | D2: Preparation Date | E2: 46059
A3: Owner Name | B3: Carla Terboven | D3: Owner Name | E3: Flora Haun
A4: Group Name | B4: CE-NECC | D4: Group Name | E4: CE-NECC
A5: Measured Mass Loading (mg/cm2) | B5: 1.28 | D5: Measured Mass Loading (mg/cm2)
A6: Bottle n# | B6: 5 | D6: Bottle n#
A7: Already used in other experiment? (y/n) | B7: n | D7: Already used in other experiment? (y/n) | E7: n
A8: Remarks | D8: Remarks | E8: first use
A9: Recipe ID | B9: CR_Cu_SD_0001 | D9: Recipe ID | E9: AR_Ir_SD_0002
A12: Cathode Recipe | D12: Anode Recipe
A13: Recipe Name | B13: {=INDEX('Recipe Mappings'!H2:S21,ROW(A1),MATCH('Catalyst details'!B9,'Recipe Mappings'!H1:S1,0))} -> Cu 9% Nafion | D13: Recipe Name | E13: {=INDEX('Recipe Mappings'!B2:G21,ROW(A1),MATCH('Catalyst details'!E9,'Recipe Mappings'!B1:G1,0))} -> Ir on Titanium
A14: Element | B14: {=INDEX('Recipe Mappings'!H2:S21,ROW(A2),MATCH('Catalyst details'!B9,'Recipe Mappings'!H1:S1,0))} -> Cu | D14: Element | E14: {=INDEX('Recipe Mappings'!B2:G21,ROW(A2),MATCH('Catalyst details'!E9,'Recipe Mappings'!B1:G1,0))} -> Ir
A15: Element Mass (mg) | B15: {=INDEX('Recipe Mappings'!H2:S21,ROW(A3),MATCH('Catalyst details'!B9,'Recipe Mappings'!H1:S1,0))} -> 200 | D15: Element Mass (mg) | E15: {=INDEX('Recipe Mappings'!B2:G21,ROW(A3),MATCH('Catalyst details'!E9,'Recipe Mappings'!B1:G1,0))} -> 190
A16: Solvent 1 Type | B16: {=INDEX('Recipe Mappings'!H2:S21,ROW(A4),MATCH('Catalyst details'!B9,'Recipe Mappings'!H1:S1,0))} -> Isopropanol | D16: Solvent 1 Type | E16: {=INDEX('Recipe Mappings'!B2:G21,ROW(A4),MATCH('Catalyst details'!E9,'Recipe Mappings'!B1:G1,0))} -> H20
A17: Solvent 1 Volume (ml) | B17: {=INDEX('Recipe Mappings'!H2:S21,ROW(A5),MATCH('Catalyst details'!B9,'Recipe Mappings'!H1:S1,0))} -> 10 | D17: Solvent 1 Volume (ml) | E17: {=INDEX('Recipe Mappings'!B2:G21,ROW(A5),MATCH('Catalyst details'!E9,'Recipe Mappings'!B1:G1,0))} -> 4.75
A18: Solvent 2 Type | B18: {=INDEX('Recipe Mappings'!H2:S21,ROW(A6),MATCH('Catalyst details'!B9,'Recipe Mappings'!H1:S1,0))} -> H2O | D18: Solvent 2 Type | E18: {=INDEX('Recipe Mappings'!B2:G21,ROW(A6),MATCH('Catalyst details'!E9,'Recipe Mappings'!B1:G1,0))} -> Isopropanol
A19: Solvent 2 Volume (ml) | B19: {=INDEX('Recipe Mappings'!H2:S21,ROW(A7),MATCH('Catalyst details'!B9,'Recipe Mappings'!H1:S1,0))} -> 10 | D19: Solvent 2 Volume (ml) | E19: {=INDEX('Recipe Mappings'!B2:G21,ROW(A7),MATCH('Catalyst details'!E9,'Recipe Mappings'!B1:G1,0))} -> 4.75
A20: Ionomer 1 Type | B20: {=INDEX('Recipe Mappings'!H2:S21,ROW(A8),MATCH('Catalyst details'!B9,'Recipe Mappings'!H1:S1,0))} -> Nafion perfluorinated resin solution | D20: Ionomer 1 Type | E20: {=INDEX('Recipe Mappings'!B2:G21,ROW(A8),MATCH('Catalyst details'!E9,'Recipe Mappings'!B1:G1,0))} -> Sustanion XA-9 5% in Ethanol
A21: Ionomer 1 Mass (mg) | B21: {=INDEX('Recipe Mappings'!H2:S21,ROW(A9),MATCH('Catalyst details'!B9,'Recipe Mappings'!H1:S1,0))} -> 420 | D21: Ionomer 1 Mass (mg) | E21: {=INDEX('Recipe Mappings'!B2:G21,ROW(A9),MATCH('Catalyst details'!E9,'Recipe Mappings'!B1:G1,0))} -> 670
A22: Ionomer 2 Type | B22: {=INDEX('Recipe Mappings'!H2:S21,ROW(A10),MATCH('Catalyst details'!B9,'Recipe Mappings'!H1:S1,0))} | D22: Ionomer 2 Type | E22: {=INDEX('Recipe Mappings'!B2:G21,ROW(A10),MATCH('Catalyst details'!E9,'Recipe Mappings'!B1:G1,0))}
A23: Ionomer 2 Mass (mg) | B23: {=INDEX('Recipe Mappings'!H2:S21,ROW(A11),MATCH('Catalyst details'!B9,'Recipe Mappings'!H1:S1,0))} | D23: Ionomer 2 Mass (mg) | E23: {=INDEX('Recipe Mappings'!B2:G21,ROW(A11),MATCH('Catalyst details'!E9,'Recipe Mappings'!B1:G1,0))}
A24: Deposition Method | B24: {=INDEX('Recipe Mappings'!H2:S21,ROW(A12),MATCH('Catalyst details'!B9,'Recipe Mappings'!H1:S1,0))} -> Spray Dep | D24: Deposition Method | E24: {=INDEX('Recipe Mappings'!B2:G21,ROW(A12),MATCH('Catalyst details'!E9,'Recipe Mappings'!B1:G1,0))} -> Spray Dep
A25: Deposition Temperature (°C) | B25: {=INDEX('Recipe Mappings'!H2:S21,ROW(A13),MATCH('Catalyst details'!B9,'Recipe Mappings'!H1:S1,0))} -> 185 | D25: Deposition Temperature (°C) | E25: {=INDEX('Recipe Mappings'!B2:G21,ROW(A13),MATCH('Catalyst details'!E9,'Recipe Mappings'!B1:G1,0))} -> 180
A26: N2 Deposition Pressure (bar) | B26: {=INDEX('Recipe Mappings'!H2:S21,ROW(A14),MATCH('Catalyst details'!B9,'Recipe Mappings'!H1:S1,0))} -> 2 | D26: N2 Deposition Pressure (bar) | E26: {=INDEX('Recipe Mappings'!B2:G21,ROW(A14),MATCH('Catalyst details'!E9,'Recipe Mappings'!B1:G1,0))} -> 2
A27: Substrate | B27: {=INDEX('Recipe Mappings'!H2:S21,ROW(A15),MATCH('Catalyst details'!B9,'Recipe Mappings'!H1:S1,0))} -> Freudenberg H23C6 | D27: Substrate | E27: {=INDEX('Recipe Mappings'!B2:G21,ROW(A15),MATCH('Catalyst details'!E9,'Recipe Mappings'!B1:G1,0))} -> Titanium
A28: Substrate Dimension | B28: {=INDEX('Recipe Mappings'!H2:S21,ROW(A16),MATCH('Catalyst details'!B9,'Recipe Mappings'!H1:S1,0))} -> 14 x 4 | D28: Substrate Dimension | E28: {=INDEX('Recipe Mappings'!B2:G21,ROW(A16),MATCH('Catalyst details'!E9,'Recipe Mappings'!B1:G1,0))} -> frit
A29: Substrate Total Area (cm²) | B29: {=INDEX('Recipe Mappings'!H2:S21,ROW(A17),MATCH('Catalyst details'!B9,'Recipe Mappings'!H1:S1,0))} -> 54 | D29: Substrate Total Area (cm²) | E29: {=INDEX('Recipe Mappings'!B2:G21,ROW(A17),MATCH('Catalyst details'!E9,'Recipe Mappings'!B1:G1,0))}
A30: Substrate Cleaning | B30: {=INDEX('Recipe Mappings'!H2:S21,ROW(A18),MATCH('Catalyst details'!B9,'Recipe Mappings'!H1:S1,0))} | D30: Substrate Cleaning | E30: {=INDEX('Recipe Mappings'!B2:G21,ROW(A18),MATCH('Catalyst details'!E9,'Recipe Mappings'!B1:G1,0))}
A31: Mass Loading (mg/cm2) | B31: {=INDEX('Recipe Mappings'!H2:S21,ROW(A19),MATCH('Catalyst details'!B9,'Recipe Mappings'!H1:S1,0))} -> 1 | D31: Mass Loading (mg/cm2) | E31: {=INDEX('Recipe Mappings'!B2:G21,ROW(A19),MATCH('Catalyst details'!E9,'Recipe Mappings'!B1:G1,0))}
A32: Recipe Remarks | B32: {=INDEX('Recipe Mappings'!H2:S21,ROW(A20),MATCH('Catalyst details'!B9,'Recipe Mappings'!H1:S1,0))} | D32: Recipe Remarks | E32: {=INDEX('Recipe Mappings'!B2:G21,ROW(A20),MATCH('Catalyst details'!E9,'Recipe Mappings'!B1:G1,0))}
A34: Browse NOMAD Recipe IDs
A35: https://nomad-hzb-ce.de/nomad-oasis/gui/upload/id/ZAhi-HGrQbu7ccrEkl_jaw
A41: Deposition methods | B41: Representation in ID
A42: Spray Dep | B42: SD
A43: Ultrasonic Nozzle | B43: UN
A44: Dropcast | B44: DC

Sheet Experimental details
B1: Please enter your data in this column | D1: Example Data
A2: Experiment Name
A3: User Name
A4: Cell type | D4: Zero-Gap
A5: Reference Electrode (y/n) | D5: y
A6: Reference Electrode Type | D6: Ag/AgCl
A7: Derivation with Motherelectrode (Ag/AgCl) [mV]
A8: Cathode Geometric Area (cm²) | D8: 8
A9: Membrane Type | D9: AEM
A10: Membrane Name | D10: PiperION
A11: Membrane Thickness (µm) | D11: 40
A12: Membrane Remarks
A13: Gasket Thickness (µm) | D13: 11
A14: Anolyte Type | D14: LiOH
A15: Anolyte Conc. (M) | D15: 0.05
A16: Anolyte Flow Rate (ml/min) | D16: 11.6
A17: Anolyte Volume (ml) | D17: 25
A18: Humidifier (y/n) | D18: n
A19: Humidifier Temperature (°C)
A20: Water Trap Volume (ml) | D20: 10
A21: Feed Gas 1 | B21: CO | D21: CO
A22: Feed Gas Flow Rate 1 (ml/min) | B22: 30 | D22: 30
A23: Feed Gas 2
A24: Feed Gas Flow Rate 2 (ml/min)
A25: Bleedline Flow Rate (ml/min) | B25: 10 | D25: 10
A26: Nitrogen Start Value (ppm) | B26: 244522 | D26: 244522
A27: pH measured | B27: y | D27: yes
A28: CP/CA | B28: CP | D28: CP
A29: EC Seq start time | B29: 0.54546296 | D29: 0.54546296
A30: Remarks
A31: Cathode ID
A32: Anode ID
A34: Browse NOMAD IDs
A35: Cathode IDs | B35: https://nomad-hzb-ce.de/nomad-oasis/gui/upload/id/IP-YgHuAT1u6c4kiGr4y_w
A36: Anode IDs | B36: https://nomad-hzb-ce.de/nomad-oasis/gui/upload/id/pjPLYsM6Q9Ctugh1gAWypA
B40: Cell Types
B41: Zero-Gap
B42: Catholyte Flow
B43: H-Cell
B45: Ref electrode types
...

Sheet Raw Data
A1: FID | Y1: TCD | AM1: Potentiostat | AU1: Thermocouple | BC1: PH
A2: Experiment name | B2: Date | C2: Time | D2: Gas type | E2: RT | F2: area | G2: ppm value | I2: Gas type | J2: RT | K2: area | L2: ppm value | N2: Gas type | O2: RT | P2: area | Q2: ppm value | S2: Gas type | T2: RT | U2: area | V2: ppm value | Y2: Experiment name | AB2: Gas type | AC2: RT | AD2: area | AE2: ppm value | AG2: Gas type | AH2: RT | AI2: area | AJ2: ppm value | AM2: time/s | AN2: Ewe-Ece/V | AO2: I/mA | AP2: dQ/C | AQ2: <Ece>/V | AR2: <Ewe/V> | AU2: C:\Users\CO2\Desktop\Sid\DAQ_FPC\231113_CO.WDH - 13/11/2023 09:48:39 | BC2: pH Time | BD2: pH | BE2: Start:12:58:10
A3: 251217_FID01.CHR | B3: 46008 | C3: 0.52378472 | D3: CO | E3: 0 | F3: 0 | G3: 0 | H3: ppm | I3: CH4 | J3: 0 | K3: 0 | L3: 0 | M3: ppm | N3: C2H4 | O3: 0 | P3: 0 | Q3: 0 | R3: ppm | S3: C2H6 | T3: 0 | U3: 0 | V3: 0 | W3: ppm | Y3: 251217_TCD01. | Z3: 46008 | AA3: 0.52378472 | AB3: H2 | AC3: 0 | AD3: 0 | AE3: 0 | AF3: ppm | AG3: N2 | AH3: 3.566 | AI3: 16268.416 | AJ3: 720130.1 | AK3: ppm | AM3: 12/17/2025 13:05:28.4330 | AN3: 3.9538021 | AO3: 799.62421 | AP3: 0 | AQ3: -3.7870932 | AR3: 0.16670896 | AU3: Sample Rate: 100 | BC3: 0.00069444444 | BD3: 11.514 | BG3: =(HOUR('Experimental details'!B29)*3600)+(MINUTE('Experimental details'!B29)*60)+SECOND('Experimental details'!B29) -> 47128
A4: 251217_FID02.CHR | B4: 46008 | C4: 0.5362963 | D4: CO | E4: 0 | F4: 0 | G4: 0 | H4: ppm | I4: CH4 | J4: 0 | K4: 0 | L4: 0 | M4: ppm | N4: C2H4 | O4: 0 | P4: 0 | Q4: 0 | R4: ppm | S4: C2H6 | T4: 0 | U4: 0 | V4: 0 | W4: ppm | Y4: 251217_TCD02. | Z4: 46008 | AA4: 0.5362963 | AB4: H2 | AC4: 0 | AD4: 0 | AE4: 0 | AF4: ppm | AG4: N2 | AH4: 3.916 | AI4: 758.527 | AJ4: 33576.602 | AK4: ppm | AM4: 12/17/2025 13:05:28.9330 | AN4: 3.9496801 | AO4: 799.66992 | AP4: 0.39986795 | AQ4: -3.7808692 | AR4: 0.16881077 | AU4: Date | AV4: Time Stamp Local | AW4: bar(g) | AX4: øC cathode | AY4: øC anode | AZ4: Chn 1 Events | BA4: Time | BC4: 0.0013888889 | BD4: 11.518 | BG4: =BG3+0.5 -> 47128.5 | BH4: potential | BI4: current | BJ4: row | BL4: avg current | BM4: avg pot
A5: 251217_FID03.CHR | B5: 46008 | C5: 0.5487963 | D5: CO | E5: 2.373 | F5: 2937.6436 | G5: 109032.7 | H5: ppm | I5: CH4 | J5: 3.406 | K5: 20.6855 | L5: 749.0546 | M5: ppm | N5: C2H4 | O5: 9.616 | P5: 14.8922 | Q5: 277.9495 | R5: ppm | S5: C2H6 | T5: 0 | U5: 0 | V5: 0 | W5: ppm | Y5: 251217_TCD03. | Z5: 46008 | AA5: 0.5487963 | AB5: H2 | AC5: 2.353 | AD5: 11933.113 | AE5: 31674.452 | AF5: ppm | AG5: N2 | AH5: 3.55 | AI5: 14429.985 | AJ5: 638750.99 | AK5: ppm | AM5: 12/17/2025 13:05:29.4330 | AN5: 3.9414771 | AO5: 799.53278 | AP5: 0.79971486 | AQ5: -3.7709165 | AR5: 0.17056057 | BA5: =(HOUR(AV5)*3600)+(MINUTE(AV5)*60)+SECOND(AV5) -> 0 | BC5: 0.0020833333 | BD5: 11.523 | BG5: =BG4+0.5 -> 47129 | BH5: =LOOKUP(Results!$D2,'Raw Data'!BG:BG,'Raw Data'!AQ:AQ) -> #N/A | BI5: =LOOKUP(Results!$D2,'Raw Data'!BG:BG,'Raw Data'!AO:AO) -> #N/A | BJ5: =LOOKUP(Results!$D2,'Raw Data'!BG:BG,ROW('Raw Data'!AO:AO)) -> #N/A | BK5: 40 | BL5: =AVERAGE(INDIRECT("$AO"&$BJ5&":$AO"&($BJ5-$BK$5))) -> #N/A | BM5: =AVERAGE(INDIRECT("$AQ"&$BJ5&":$AQ"&($BJ5-$BK$5))) -> #N/A
A6: 251217_FID04.CHR | B6: 46008 | C6: 0.5612963 | D6: CO | E6: 2.37 | F6: 5088.5267 | G6: 188864.23 | H6: ppm | I6: CH4 | J6: 0 | K6: 0 | L6: 0 | M6: ppm | N6: C2H4 | O6: 9.543 | P6: 666.8578 | Q6: 12446.302 | R6: ppm | S6: C2H6 | T6: 0 | U6: 0 | V6: 0 | W6: ppm | Y6: 251217_TCD04. | Z6: 46008 | AA6: 0.5612963 | AB6: H2 | AC6: 2.373 | AD6: 10883.957 | AE6: 28768.179 | AF6: ppm | AG6: N2 | AH6: 3.703 | AI6: 6366.779 | AJ6: 281828.87 | AK6: ppm | AM6: 12/17/2025 13:05:29.9330 | AN6: 3.934613 | AO6: 799.66986 | AP6: 1.1995703 | AQ6: -3.7627411 | AR6: 0.17187187 | BA6: =(HOUR(AV6)*3600)+(MINUTE(AV6)*60)+SECOND(AV6) -> 0 | BC6: 0.0027777778 | BD6: 11.528 | BG6: =BG5+0.5 -> 47129.5 | BH6: =LOOKUP(Results!$D3,'Raw Data'!BG:BG,'Raw Data'!AQ:AQ) -> #N/A | BI6: =LOOKUP(Results!$D3,'Raw Data'!BG:BG,'Raw Data'!AO:AO) -> #N/A | BJ6: =LOOKUP(Results!$D3,'Raw Data'!BG:BG,ROW('Raw Data'!AO:AO)) -> #N/A | BL6: =AVERAGE(INDIRECT("$AO"&$BJ6&":$AO"&($BJ6-$BK$5))) -> #N/A | BM6: =AVERAGE(INDIRECT("$AQ"&$BJ6&":$AQ"&($BJ6-$BK$5))) -> #N/A
A7: 251217_FID05.CHR | B7: 46008 | C7: 0.5737963 | D7: CO | E7: 2.37 | F7: 5089.7314 | G7: 188908.94 | H7: ppm | I7: CH4 | J7: 0 | K7: 0 | L7: 0 | M7: ppm | N7: C2H4 | O7: 9.546 | P7: 558.8846 | Q7: 10431.079 | R7: ppm | S7: C2H6 | T7: 0 | U7: 0 | V7: 0 | W7: ppm | Y7: 251217_TCD05. | Z7: 46008 | AA7: 0.5737963 | AB7: H2 | AC7: 2.403 | AD7: 19441.795 | AE7: 52474.299 | AF7: ppm | AG7: N2 | AH7: 3.723 | AI7: 5470.9436 | AJ7: 242174.23 | AK7: ppm | AM7: 12/17/2025 13:05:30.4330 | AN7: 3.9275296 | AO7: 799.63947 | AP7: 1.599432 | AQ7: -3.7561085 | AR7: 0.17142099 | BA7: =(HOUR(AV7)*3600)+(MINUTE(AV7)*60)+SECOND(AV7) -> 0 | BC7: 0.0034722222 | BD7: 11.53 | BG7: =BG6+0.5 -> 47130 | BH7: =LOOKUP(Results!$D4,'Raw Data'!BG:BG,'Raw Data'!AQ:AQ) -> -2.7917266 | BI7: =LOOKUP(Results!$D4,'Raw Data'!BG:BG,'Raw Data'!AO:AO) -> 800.17261 | BJ7: =LOOKUP(Results!$D4,'Raw Data'!BG:BG,ROW('Raw Data'!AO:AO)) -> 579 | BL7: =AVERAGE(INDIRECT("$AO"&$BJ7&":$AO"&($BJ7-$BK$5))) -> 800.03732 | BM7: =AVERAGE(INDIRECT("$AQ"&$BJ7&":$AQ"&($BJ7-$BK$5))) -> -2.8143897
A8: 251217_FID06.CHR | B8: 46008 | C8: 0.5862963 | D8: CO | E8: 2.383 | F8: 5024.4639 | G8: 186486.49 | H8: ppm | I8: CH4 | J8: 0 | K8: 0 | L8: 0 | M8: ppm | N8: C2H4 | O8: 9.576 | P8: 383.374 | Q8: 7155.3316 | R8: ppm | S8: C2H6 | T8: 0 | U8: 0 | V8: 0 | W8: ppm | Y8: 251217_TCD06. | Z8: 46008 | AA8: 0.5862963 | AB8: H2 | AC8: 2.416 | AD8: 27556.508 | AE8: 74952.917 | AF8: ppm | AG8: N2 | AH8: 3.723 | AI8: 5258.6772 | AJ8: 232778.15 | AK8: ppm | AM8: 12/17/2025 13:05:30.9330 | AN8: 3.9221373 | AO8: 799.86792 | AP8: 1.9993113 | AQ8: -3.7510946 | AR8: 0.17104267 | BC8: 0.0041666667 | BD8: 11.526 | BG8: =BG7+0.5 -> 47130.5 | BH8: =LOOKUP(Results!$D5,'Raw Data'!BG:BG,'Raw Data'!AQ:AQ) -> -2.9170692 | BI8: =LOOKUP(Results!$D5,'Raw Data'!BG:BG,'Raw Data'!AO:AO) -> 800.005 | BJ8: =LOOKUP(Results!$D5,'Raw Data'!BG:BG,ROW('Raw Data'!AO:AO)) -> 2739 | BL8: =AVERAGE(INDIRECT("$AO"&$BJ8&":$AO"&($BJ8-$BK$5))) -> 800.01427 | BM8: =AVERAGE(INDIRECT("$AQ"&$BJ8&":$AQ"&($BJ8-$BK$5))) -> -2.9163492
A9: 251217_FID07.CHR | B9: 46008 | C9: 0.5987963 | D9: CO | E9: 2.373 | F9: 4957.1616 | G9: 183988.52 | H9: ppm | I9: CH4 | J9: 0 | K9: 0 | L9: 0 | M9: ppm | N9: C2H4 | O9: 9.593 | P9: 165.268 | Q9: 3084.5789 | R9: ppm | S9: C2H6 | T9: 0 | U9: 0 | V9: 0 | W9: ppm | Y9: 251217_TCD07. | Z9: 46008 | AA9: 0.5987963 | AB9: H2 | AC9: 2.456 | AD9: 35337.802 | AE9: 96507.929 | AF9: ppm | AG9: N2 | AH9: 3.74 | AI9: 5046.6428 | AJ9: 223392.33 | AK9: ppm | AM9: 12/17/2025 13:05:31.4330 | AN9: 3.9185307 | AO9: 799.74603 | AP9: 2.3991983 | AQ9: -3.7471945 | AR9: 0.17133616 | BC9: 0.0048611111 | BD9: 11.527 | BG9: =BG8+0.5 -> 47131 | BH9: =LOOKUP(Results!$D6,'Raw Data'!BG:BG,'Raw Data'!AQ:AQ) -> -2.9027987 | BI9: =LOOKUP(Results!$D6,'Raw Data'!BG:BG,'Raw Data'!AO:AO) -> 800.08118 | BJ9: =LOOKUP(Results!$D6,'Raw Data'!BG:BG,ROW('Raw Data'!AO:AO)) -> 4899 | BL9: =AVERAGE(INDIRECT("$AO"&$BJ9&":$AO"&($BJ9-$BK$5))) -> 800.08153 | BM9: =AVERAGE(INDIRECT("$AQ"&$BJ9&":$AQ"&($BJ9-$BK$5))) -> -2.9031998
AM10: 12/17/2025 13:05:31.9330 | AN10: 3.9159849 | AO10: 799.71558 | AP10: 2.7990828 | AQ10: -3.7441468 | AR10: 0.17183803 | BC10: 0.0055555556 | BD10: 11.526 | BG10: =BG9+0.5 -> 47131.5 | BH10: =LOOKUP(Results!$D7,'Raw Data'!BG:BG,'Raw Data'!AQ:AQ) -> -2.7925346 | BI10: =LOOKUP(Results!$D7,'Raw Data'!BG:BG,'Raw Data'!AO:AO) -> 800.005 | BJ10: =LOOKUP(Results!$D7,'Raw Data'!BG:BG,ROW('Raw Data'!AO:AO)) -> 7059 | BL10: =AVERAGE(INDIRECT("$AO"&$BJ10&":$AO"&($BJ10-$BK$5))) -> 799.96004 | BM10: =AVERAGE(INDIRECT("$AQ"&$BJ10&":$AQ"&($BJ10-$BK$5))) -> -2.7945951
AM11: 12/17/2025 13:05:32.4330 | AN11: 3.9137928 | AO11: 799.74603 | AP11: 3.1989655 | AQ11: -3.7419202 | AR11: 0.17187272 | BC11: 0.00625 | BD11: 11.517 | BG11: =BG10+0.5 -> 47132 | BH11: =LOOKUP(Results!$D8,'Raw Data'!BG:BG,'Raw Data'!AQ:AQ) -> -2.4630585 | BI11: =LOOKUP(Results!$D8,'Raw Data'!BG:BG,'Raw Data'!AO:AO) -> 800.09644 | BJ11: =LOOKUP(Results!$D8,'Raw Data'!BG:BG,ROW('Raw Data'!AO:AO)) -> 9219 | BL11: =AVERAGE(INDIRECT("$AO"&$BJ11&":$AO"&($BJ11-$BK$5))) -> 800.03657 | BM11: =AVERAGE(INDIRECT("$AQ"&$BJ11&":$AQ"&($BJ11-$BK$5))) -> -2.4649581
AM12: 12/17/2025 13:05:32.9330 | AN12: 3.9136322 | AO12: 799.66986 | AP12: 3.5988586 | AQ12: -3.7401793 | AR12: 0.17345287 | BC12: 0.0069444444 | BD12: 11.515 | BG12: =BG11+0.5 -> 47132.5 | BH12: =LOOKUP(Results!$D9,'Raw Data'!BG:BG,'Raw Data'!AQ:AQ) -> #N/A | BI12: =LOOKUP(Results!$D9,'Raw Data'!BG:BG,'Raw Data'!AO:AO) -> #N/A | BJ12: =LOOKUP(Results!$D9,'Raw Data'!BG:BG,ROW('Raw Data'!AO:AO)) -> #N/A | BL12: =AVERAGE(INDIRECT("$AO"&$BJ12&":$AO"&($BJ12-$BK$5))) -> #N/A | BM12: =AVERAGE(INDIRECT("$AQ"&$BJ12&":$AQ"&($BJ12-$BK$5))) -> #N/A
AM13: 12/17/2025 13:05:33.4330 | AN13: 3.9134109 | AO13: 799.65466 | AP13: 3.9987466 | AQ13: -3.7388239 | AR13: 0.17458703 | BC13: 0.0076388889 | BD13: 11.509 | BG13: =BG12+0.5 -> 47133 | BH13: =LOOKUP(Results!$D10,'Raw Data'!BG:BG,'Raw Data'!AQ:AQ) -> #N/A | BI13: =LOOKUP(Results!$D10,'Raw Data'!BG:BG,'Raw Data'!AO:AO) -> #N/A | BJ13: =LOOKUP(Results!$D10,'Raw Data'!BG:BG,ROW('Raw Data'!AO:AO)) -> #N/A | BL13: =AVERAGE(INDIRECT("$AO"&$BJ13&":$AO"&($BJ13-$BK$5))) -> #N/A | BM13: =AVERAGE(INDIRECT("$AQ"&$BJ13&":$AQ"&($BJ13-$BK$5))) -> #N/A
AM14: 12/17/2025 13:05:33.9330 | AN14: 3.9135716 | AO14: 799.68512 | AP14: 4.3986278 | AQ14: -3.7378151 | AR14: 0.17575639 | BC14: 0.0083333333 | BD14: 11.504 | BG14: =BG13+0.5 -> 47133.5 | BH14: =LOOKUP(Results!$D11,'Raw Data'!BG:BG,'Raw Data'!AQ:AQ) -> #N/A | BI14: =LOOKUP(Results!$D11,'Raw Data'!BG:BG,'Raw Data'!AO:AO) -> #N/A | BJ14: =LOOKUP(Results!$D11,'Raw Data'!BG:BG,ROW('Raw Data'!AO:AO)) -> #N/A | BL14: =AVERAGE(INDIRECT("$AO"&$BJ14&":$AO"&($BJ14-$BK$5))) -> #N/A | BM14: =AVERAGE(INDIRECT("$AQ"&$BJ14&":$AQ"&($BJ14-$BK$5))) -> #N/A
AM15: 12/17/2025 13:05:34.4330 | AN15: 3.912205 | AO15: 799.73077 | AP15: 4.7985024 | AQ15: -3.7369845 | AR15: 0.17522056 | BC15: 0.0090277778 | BD15: 11.5 | BG15: =BG14+0.5 -> 47134 | BH15: =LOOKUP(Results!$D12,'Raw Data'!BG:BG,'Raw Data'!AQ:AQ) -> #N/A | BI15: =LOOKUP(Results!$D12,'Raw Data'!BG:BG,'Raw Data'!AO:AO) -> #N/A | BJ15: =LOOKUP(Results!$D12,'Raw Data'!BG:BG,ROW('Raw Data'!AO:AO)) -> #N/A | BL15: =AVERAGE(INDIRECT("$AO"&$BJ15&":$AO"&($BJ15-$BK$5))) -> #N/A | BM15: =AVERAGE(INDIRECT("$AQ"&$BJ15&":$AQ"&($BJ15-$BK$5))) -> #N/A
AM16: 12/17/2025 13:05:34.9330 | AN16: 3.910934 | AO16: 799.82214 | AP16: 5.1983743 | AQ16: -3.7364249 | AR16: 0.17450893 | BC16: 0.0097222222 | BD16: 11.494 | BG16: =BG15+0.5 -> 47134.5 | BH16: =LOOKUP(Results!$D13,'Raw Data'!BG:BG,'Raw Data'!AQ:AQ) -> #N/A | BI16: =LOOKUP(Results!$D13,'Raw Data'!BG:BG,'Raw Data'!AO:AO) -> #N/A | BJ16: =LOOKUP(Results!$D13,'Raw Data'!BG:BG,ROW('Raw Data'!AO:AO)) -> #N/A | BL16: =AVERAGE(INDIRECT("$AO"&$BJ16&":$AO"&($BJ16-$BK$5))) -> #N/A | BM16: =AVERAGE(INDIRECT("$AQ"&$BJ16&":$AQ"&($BJ16-$BK$5))) -> #N/A
AM17: 12/17/2025 13:05:35.4330 | AN17: 3.9108536 | AO17: 799.83746 | AP17: 5.5982494 | AQ17: -3.7362089 | AR17: 0.17464478 | BC17: 0.010416667 | BD17: 11.486 | BG17: =BG16+0.5 -> 47135 | BH17: =LOOKUP(Results!$D14,'Raw Data'!BG:BG,'Raw Data'!AQ:AQ) -> #N/A | BI17: =LOOKUP(Results!$D14,'Raw Data'!BG:BG,'Raw Data'!AO:AO) -> #N/A | BJ17: =LOOKUP(Results!$D14,'Raw Data'!BG:BG,ROW('Raw Data'!AO:AO)) -> #N/A | BL17: =AVERAGE(INDIRECT("$AO"&$BJ17&":$AO"&($BJ17-$BK$5))) -> #N/A | BM17: =AVERAGE(INDIRECT("$AQ"&$BJ17&":$AQ"&($BJ17-$BK$5))) -> #N/A
AM18: 12/17/2025 13:05:35.9330 | AN18: 3.9114537 | AO18: 799.65466 | AP18: 5.9981279 | AQ18: -3.7361226 | AR18: 0.1753311 | BC18: 0.011111111 | BD18: 11.483 | BG18: =BG17+0.5 -> 47135.5 | BH18: =LOOKUP(Results!$D15,'Raw Data'!BG:BG,'Raw Data'!AQ:AQ) -> #N/A | BI18: =LOOKUP(Results!$D15,'Raw Data'!BG:BG,'Raw Data'!AO:AO) -> #N/A | BJ18: =LOOKUP(Results!$D15,'Raw Data'!BG:BG,ROW('Raw Data'!AO:AO)) -> #N/A | BL18: =AVERAGE(INDIRECT("$AO"&$BJ18&":$AO"&($BJ18-$BK$5))) -> #N/A | BM18: =AVERAGE(INDIRECT("$AQ"&$BJ18&":$AQ"&($BJ18-$BK$5))) -> #N/A
AM19: 12/17/2025 13:05:36.4330 | AN19: 3.9116197 | AO19: 799.71558 | AP19: 6.3980064 | AQ19: -3.7361128 | AR19: 0.17550693 | BC19: 0.011805556 | BD19: 11.478 | BG19: =BG18+0.5 -> 47136 | BH19: =LOOKUP(Results!$D16,'Raw Data'!BG:BG,'Raw Data'!AQ:AQ) -> #N/A | BI19: =LOOKUP(Results!$D16,'Raw Data'!BG:BG,'Raw Data'!AO:AO) -> #N/A | BJ19: =LOOKUP(Results!$D16,'Raw Data'!BG:BG,ROW('Raw Data'!AO:AO)) -> #N/A | BL19: =AVERAGE(INDIRECT("$AO"&$BJ19&":$AO"&($BJ19-$BK$5))) -> #N/A | BM19: =AVERAGE(INDIRECT("$AQ"&$BJ19&":$AQ"&($BJ19-$BK$5))) -> #N/A
AM20: 12/17/2025 13:05:36.9330 | AN20: 3.9124973 | AO20: 799.82214 | AP20: 6.797884 | AQ20: -3.7364922 | AR20: 0.17600517 | BC20: 0.0125 | BD20: 11.474 | BG20: =BG19+0.5 -> 47136.5 | BH20: =LOOKUP(Results!$D17,'Raw Data'!BG:BG,'Raw Data'!AQ:AQ) -> #N/A | BI20: =LOOKUP(Results!$D17,'Raw Data'!BG:BG,'Raw Data'!AO:AO) -> #N/A | BJ20: =LOOKUP(Results!$D17,'Raw Data'!BG:BG,ROW('Raw Data'!AO:AO)) -> #N/A | BL20: =AVERAGE(INDIRECT("$AO"&$BJ20&":$AO"&($BJ20-$BK$5))) -> #N/A | BM20: =AVERAGE(INDIRECT("$AQ"&$BJ20&":$AQ"&($BJ20-$BK$5))) -> #N/A
AM21: 12/17/2025 13:05:37.4330 | AN21: 3.9139702 | AO21: 799.74603 | AP21: 7.197773 | AQ21: -3.7368996 | AR21: 0.17707065 | BC21: 0.013194444 | BD21: 11.47 | BG21: =BG20+0.5 -> 47137 | BH21: =LOOKUP(Results!$D18,'Raw Data'!BG:BG,'Raw Data'!AQ:AQ) -> #N/A | BI21: =LOOKUP(Results!$D18,'Raw Data'!BG:BG,'Raw Data'!AO:AO) -> #N/A | BJ21: =LOOKUP(Results!$D18,'Raw Data'!BG:BG,ROW('Raw Data'!AO:AO)) -> #N/A | BL21: =AVERAGE(INDIRECT("$AO"&$BJ21&":$AO"&($BJ21-$BK$5))) -> #N/A | BM21: =AVERAGE(INDIRECT("$AQ"&$BJ21&":$AQ"&($BJ21-$BK$5))) -> #N/A
AM22: 12/17/2025 13:05:37.9330 | AN22: 3.9151173 | AO22: 799.77649 | AP22: 7.597671 | AQ22: -3.737355 | AR22: 0.17776224 | BC22: 0.013888889 | BD22: 11.465 | BG22: =BG21+0.5 -> 47137.5 | BH22: =LOOKUP(Results!$D19,'Raw Data'!BG:BG,'Raw Data'!AQ:AQ) -> #N/A | BI22: =LOOKUP(Results!$D19,'Raw Data'!BG:BG,'Raw Data'!AO:AO) -> #N/A | BJ22: =LOOKUP(Results!$D19,'Raw Data'!BG:BG,ROW('Raw Data'!AO:AO)) -> #N/A | BL22: =AVERAGE(INDIRECT("$AO"&$BJ22&":$AO"&($BJ22-$BK$5))) -> #N/A | BM22: =AVERAGE(INDIRECT("$AQ"&$BJ22&":$AQ"&($BJ22-$BK$5))) -> #N/A
AM23: 12/17/2025 13:05:38.4330 | AN23: 3.9164078 | AO23: 799.62415 | AP23: 7.9975772 | AQ23: -3.7379556 | AR23: 0.17845236 | BC23: 0.014583333 | BD23: 11.461 | BG23: =BG22+0.5 -> 47138
AM24: 12/17/2025 13:05:38.9330 | AN24: 3.9174125 | AO24: 799.88318 | AP24: 8.397481 | AQ24: -3.7385747 | AR24: 0.17883778 | BC24: 0.015277778 | BD24: 11.457 | BG24: =BG23+0.5 -> 47138.5
AM25: 12/17/2025 13:05:39.4330 | AN25: 3.9191556 | AO25: 799.82214 | AP25: 8.7973833 | AQ25: -3.7393165 | AR25: 0.17983924 | BC25: 0.015972222 | BD25: 11.452 | BG25: =BG24+0.5 -> 47139
AM26: 12/17/2025 13:05:39.9330 | AN26: 3.9217193 | AO26: 799.85266 | AP26: 9.1972933 | AQ26: -3.7401359 | AR26: 0.18158336 | BC26: 0.016666667 | BD26: 11.448 | BG26: =BG25+0.5 -> 47139.5
AM27: 12/17/2025 13:05:40.4330 | AN27: 3.9234381 | AO27: 799.8222 | AP27: 9.5972042 | AQ27: -3.7409718 | AR27: 0.18246628 | BC27: 0.017361111 | BD27: 11.444 | BG27: =BG26+0.5 -> 47140
AM28: 12/17/2025 13:05:40.9330 | AN28: 3.9257038 | AO28: 799.88318 | AP28: 9.9971189 | AQ28: -3.7419322 | AR28: 0.18377155 | BC28: 0.018055556 | BD28: 11.441 | BG28: =BG27+0.5 -> 47140.5
AM29: 12/17/2025 13:05:41.4330 | AN29: 3.9280195 | AO29: 799.88318 | AP29: 10.397038 | AQ29: -3.7428594 | AR29: 0.18516007 | BC29: 0.01875 | BD29: 11.436 | BG29: =BG28+0.5 -> 47141
AM30: 12/17/2025 13:05:41.9330 | AN30: 3.9296794 | AO30: 799.91364 | AP30: 10.796959 | AQ30: -3.743643 | AR30: 0.1860363 | BC30: 0.019444444 | BD30: 11.433 | BG30: =BG29+0.5 -> 47141.5
AM31: 12/17/2025 13:05:42.4330 | AN31: 3.931793 | AO31: 799.80701 | AP31: 11.196876 | AQ31: -3.7445664 | AR31: 0.18722647 | BC31: 0.020138889 | BD31: 11.429 | BG31: =BG30+0.5 -> 47142
AM32: 12/17/2025 13:05:42.9330 | AN32: 3.9327958 | AO32: 799.89838 | AP32: 11.596789 | AQ32: -3.7454786 | AR32: 0.18731715 | BC32: 0.020833333 | BD32: 11.427 | BG32: =BG31+0.5 -> 47142.5
AM33: 12/17/2025 13:05:43.4330 | AN33: 3.9348037 | AO33: 799.85266 | AP33: 11.996703 | AQ33: -3.7463949 | AR33: 0.18840875 | BC33: 0.021527778 | BD33: 11.424 | BG33: =BG32+0.5 -> 47143
AM34: 12/17/2025 13:05:43.9330 | AN34: 3.9367151 | AO34: 799.79175 | AP34: 12.396611 | AQ34: -3.7472649 | AR34: 0.18945016 | BC34: 0.022222222 | BD34: 11.419 | BG34: =BG33+0.5 -> 47143.5
... AM156: 12/17/2025 13:06:44.9330 | AN156: 4.066258 | AO156: 799.97449 | AP156: 61.187824 | AQ156: -3.7778485 | AR156: 0.28840956 | BC156: 0.10694444 | BD156: 11.265 | BG156: =BG155+0.5 -> 47204.5
AM157: 12/17/2025 13:06:45.4330 | AN157: 4.0665736 | AO157: 799.98975 | AP157: 61.587818 | AQ157: -3.7774508 | AR157: 0.28912285 | BG157: =BG156+0.5 -> 47205
AM158: 12/17/2025 13:06:45.9330 | AN158: 4.0660582 | AO158: 799.89832 | AP158: 61.987812 | AQ158: -3.7772636 | AR158: 0.28879446 | BG158: =BG157+0.5 -> 47205.5
AM159: 12/17/2025 13:06:46.4330 | AN159: 4.0668716 | AO159: 799.97455 | AP159: 62.387798 | AQ159: -3.7772689 | AR159: 0.28960276 | BG159: =BG158+0.5 -> 47206
AM160: 12/17/2025 13:06:46.9330 | AN160: 4.0679293 | AO160: 800.05066 | AP160: 62.787769 | AQ160: -3.7771738 | AR160: 0.29075554 | BG160: =BG159+0.5 -> 47206.5
AM161: 12/17/2025 13:06:47.4330 | AN161: 4.0686083 | AO161: 799.98975 | AP161: 63.18774 | AQ161: -3.7769403 | AR161: 0.29166818 | BG161: =BG160+0.5 -> 47207
...

Sheet Results
A1: Inj Namen | B1: Date | C1: Time | D1: Injection Time in s | E1: Current(mA) | F1: Cell Voltage | G1: Nitrogen (ppm) | H1: Total flow rate (ml/min) | I1: Temp Cathode (0C) | J1: Temp Anode (0C) | K1: Pressure (barg) | L1: CO (ppm) | M1: CO (ml/min) | N1: CO Q/t (mc/min) | O1: CO I (mA) | P1: CO FE (%) | Q1: CH4 (ppm) | R1: CH4 (ml/min) | S1: CH4 Q/t (mc/min) | T1: CH4 I (mA) | U1: CH4 FE (%) | V1: C2H4 (ppm) | W1: C2H4 (ml/min) | X1: C2H4 Q/t (mc/min) | Y1: C2H4 I (mA) | Z1: C2H4 FE (%) | AA1: H2 (ppm) | AB1: H2 (ml/min) | AC1: H2 Q/t (mc/min) | AD1: H2 I (mA) | AE1: H2 FE (%) | AF1: Total FE (%) | AH1: pH | AJ1: Feed Gas | AK1: Electrons Used CO | AL1: Electrons Used CH4 | AM1: Electrons Used C2H4 | AN1: Electrons Used H2
A2: ='Raw Data'!A3 -> 251217_FID01.CHR | B2: ='Raw Data'!B3 -> 46008 | C2: ='Raw Data'!C3 -> 0.52378472 | D2: =(HOUR(C2)*3600)+(MINUTE(C2)*60)+SECOND(C2) -> 45255 | E2: ='Raw Data'!BL5 -> #N/A | F2: ='Raw Data'!BM5 -> #N/A | G2: ='Experimental details'!$B$26 -> 244522 | H2: =10*G2*('Experimental details'!$B$22+'Experimental details'!$B$25)/'Experimental details'!$B$25/'Raw Data'!AJ3 -> 13.582101 | I2: =LOOKUP(Results!$D2,'Raw Data'!BA:BA,'Raw Data'!AX:AX) -> 0 | J2: =LOOKUP(Results!$D2,'Raw Data'!BA:BA,'Raw Data'!AY:AY) -> 0 | K2: =LOOKUP(Results!$D2,'Raw Data'!BA:BA,'Raw Data'!AW:AW) -> 0 | L2: ='Raw Data'!G3 -> 0 | M2: =H2*L2/1000000 -> 0 | N2: =M2*AK2*96485/0.082057/298 -> 0 | O2: =N2/60 -> 0 | P2: =-O2*100/E2 -> #N/A | Q2: ='Raw Data'!L3 -> 0 | R2: =Q2*H2/1000000 -> 0 | S2: =R2*AL2*96485/0.082057/298 -> 0 | T2: =S2/60 -> 0 | U2: =ABS(-T2*100/E2) -> #N/A | V2: ='Raw Data'!Q3 -> 0 | W2: =H2*V2/1000000 -> 0 | X2: =W2*AM2*96485/0.082057/298 -> 0 | Y2: =X2/60 -> 0 | Z2: =ABS(-Y2*100/E2) -> #N/A | AA2: ='Raw Data'!AE3 -> 0 | AB2: =AA2*H2/1000000 -> 0 | AC2: =AB2*AN2*96485/0.082057/298 -> 0 | AD2: =AC2/60 -> 0 | AE2: =ABS(-AD2*100/E2) -> #N/A | AF2: =SUM(AE2+Z2+U2) -> #N/A | AG2: Start | AJ2: ='Experimental details'!B21 -> CO | AK2: =IF(AJ2="CO",0,2) -> 0 | AL2: =IF(AJ2="CO",6,8) -> 6 | AM2: =IF(AJ2="CO",8,12) -> 8 | AN2: 2
A3: ='Raw Data'!A4 -> 251217_FID02.CHR | B3: ='Raw Data'!B3 -> 46008 | C3: ='Raw Data'!C4 -> 0.5362963 | D3: =(HOUR(C3)*3600)+(MINUTE(C3)*60)+SECOND(C3) -> 46336 | E3: ='Raw Data'!BL6 -> #N/A | F3: ='Raw Data'!BM6 -> #N/A | G3: ='Experimental details'!$B$26 -> 244522 | H3: =10*G3*('Experimental details'!$B$22+'Experimental details'!$B$25)/'Experimental details'!$B$25/'Raw Data'!AJ4 -> 291.30047 | I3: =LOOKUP(Results!$D3,'Raw Data'!BA:BA,'Raw Data'!AX:AX) -> 0 | J3: =LOOKUP(Results!$D3,'Raw Data'!BA:BA,'Raw Data'!AY:AY) -> 0 | K3: =LOOKUP(Results!$D3,'Raw Data'!BA:BA,'Raw Data'!AW:AW) -> 0 | L3: ='Raw Data'!G4 -> 0 | M3: =H3*L3/1000000 -> 0 | N3: =M3*AK3*96485/0.082057/298 -> 0 | O3: =N3/60 -> 0 | P3: =-O3*100/E3 -> #N/A | Q3: ='Raw Data'!L4 -> 0 | R3: =Q3*H3/1000000 -> 0 | S3: =R3*AL3*96485/0.082057/298 -> 0 | T3: =S3/60 -> 0 | U3: =ABS(-T3*100/E3) -> #N/A | V3: ='Raw Data'!Q4 -> 0 | W3: =H3*V3/1000000 -> 0 | X3: =W3*AM3*96485/0.082057/298 -> 0 | Y3: =X3/60 -> 0 | Z3: =ABS(-Y3*100/E3) -> #N/A | AA3: ='Raw Data'!AE4 -> 0 | AB3: =AA3*H3/1000000 -> 0 | AC3: =AB3*AN3*96485/0.082057/298 -> 0 | AD3: =AC3/60 -> 0 | AE3: =ABS(-AD3*100/E3) -> #N/A | AF3: =SUM(AE3+Z3+U3) -> #N/A | AG3: End | AJ3: ='Experimental details'!B21 -> CO | AK3: =IF(AJ3="CO",0,2) -> 0 | AL3: =IF(AJ3="CO",6,8) -> 6 | AM3: =IF(AJ3="CO",8,12) -> 8 | AN3: 2
A4: ='Raw Data'!A5 -> 251217_FID03.CHR | B4: ='Raw Data'!B3 -> 46008 | C4: ='Raw Data'!C5 -> 0.5487963 | D4: =(HOUR(C4)*3600)+(MINUTE(C4)*60)+SECOND(C4) -> 47416 | E4: ='Raw Data'!BL7 -> 800.03732 | F4: ='Raw Data'!BM7 -> -2.8143897 | G4: ='Experimental details'!$B$26 -> 244522 | H4: =10*G4*('Experimental details'!$B$22+'Experimental details'!$B$25)/'Experimental details'!$B$25/'Raw Data'!AJ5 -> 15.312508 | I4: =LOOKUP(Results!$D4,'Raw Data'!BA:BA,'Raw Data'!AX:AX) -> 0 | J4: =LOOKUP(Results!$D4,'Raw Data'!BA:BA,'Raw Data'!AY:AY) -> 0 | K4: =LOOKUP(Results!$D4,'Raw Data'!BA:BA,'Raw Data'!AW:AW) -> 0 | L4: ='Raw Data'!G5 -> 109032.7 | M4: =H4*L4/1000000 -> 1.6695641 | N4: =M4*AK4*96485/0.082057/298 -> 0 | O4: =N4/60 -> 0 | P4: =-O4*100/E4 -> 0 | Q4: ='Raw Data'!L5 -> 749.0546 | R4: =Q4*H4/1000000 -> 0.011469905 | S4: =R4*AL4*96485/0.082057/298 -> 271.54322 | T4: =S4/60 -> 4.5257204 | U4: =ABS(-T4*100/E4) -> 0.56568866 | V4: ='Raw Data'!Q5 -> 277.9495 | W4: =H4*V4/1000000 -> 0.0042561041 | X4: =W4*AM4*96485/0.082057/298 -> 134.34767 | Y4: =X4/60 -> 2.2391278 | Z4: =ABS(-Y4*100/E4) -> 0.27987792 | AA4: ='Raw Data'!AE5 -> 31674.452 | AB4: =AA4*H4/1000000 -> 0.48501532 | AC4: =AB4*AN4*96485/0.082057/298 -> 3827.4837 | AD4: =AC4/60 -> 63.791395 | AE4: =ABS(-AD4*100/E4) -> 7.9735525 | AF4: =SUM(AE4+Z4+U4) -> 8.8191191 | AJ4: ='Experimental details'!B21 -> CO | AK4: =IF(AJ4="CO",0,2) -> 0 | AL4: =IF(AJ4="CO",6,8) -> 6 | AM4: =IF(AJ4="CO",8,12) -> 8 | AN4: 2
A5: ='Raw Data'!A6 -> 251217_FID04.CHR | B5: ='Raw Data'!B3 -> 46008 | C5: ='Raw Data'!C6 -> 0.5612963 | D5: =(HOUR(C5)*3600)+(MINUTE(C5)*60)+SECOND(C5) -> 48496 | E5: ='Raw Data'!BL8 -> 800.01427 | F5: ='Raw Data'!BM8 -> -2.9163492 | G5: ='Experimental details'!$B$26 -> 244522 | H5: =10*G5*('Experimental details'!$B$22+'Experimental details'!$B$25)/'Experimental details'!$B$25/'Raw Data'!AJ6 -> 34.705033 | I5: =LOOKUP(Results!$D5,'Raw Data'!BA:BA,'Raw Data'!AX:AX) -> 0 | J5: =LOOKUP(Results!$D5,'Raw Data'!BA:BA,'Raw Data'!AY:AY) -> 0 | K5: =LOOKUP(Results!$D5,'Raw Data'!BA:BA,'Raw Data'!AW:AW) -> 0 | L5: ='Raw Data'!G6 -> 188864.23 | M5: =H5*L5/1000000 -> 6.5545391 | N5: =M5*AK5*96485/0.082057/298 -> 0 | O5: =N5/60 -> 0 | P5: =-O5*100/E5 -> 0 | Q5: ='Raw Data'!L6 -> 0 | R5: =Q5*H5/1000000 -> 0 | S5: =R5*AL5*96485/0.082057/298 -> 0 | T5: =S5/60 -> 0 | U5: =ABS(-T5*100/E5) -> 0 | V5: ='Raw Data'!Q6 -> 12446.302 | W5: =H5*V5/1000000 -> 0.43194933 | X5: =W5*AM5*96485/0.082057/298 -> 13634.86 | Y5: =X5/60 -> 227.24767 | Z5: =ABS(-Y5*100/E5) -> 28.405452 | AA5: ='Raw Data'!AE6 -> 28768.179 | AB5: =AA5*H5/1000000 -> 0.9984006 | AC5: =AB5*AN5*96485/0.082057/298 -> 7878.8482 | AD5: =AC5/60 -> 131.31414 | AE5: =ABS(-AD5*100/E5) -> 16.413974 | AF5: =SUM(AE5+Z5+U5) -> 44.819426 | AJ5: ='Experimental details'!B21 -> CO | AK5: =IF(AJ5="CO",0,2) -> 0 | AL5: =IF(AJ5="CO",6,8) -> 6 | AM5: =IF(AJ5="CO",8,12) -> 8 | AN5: 2
A6: ='Raw Data'!A7 -> 251217_FID05.CHR | B6: ='Raw Data'!B3 -> 46008 | C6: ='Raw Data'!C7 -> 0.5737963 | D6: =(HOUR(C6)*3600)+(MINUTE(C6)*60)+SECOND(C6) -> 49576 | E6: ='Raw Data'!BL9 -> 800.08153 | F6: ='Raw Data'!BM9 -> -2.9031998 | G6: ='Experimental details'!$B$26 -> 244522 | H6: =10*G6*('Experimental details'!$B$22+'Experimental details'!$B$25)/'Experimental details'!$B$25/'Raw Data'!AJ7 -> 40.387781 | I6: =LOOKUP(Results!$D6,'Raw Data'!BA:BA,'Raw Data'!AX:AX) -> 0 | J6: =LOOKUP(Results!$D6,'Raw Data'!BA:BA,'Raw Data'!AY:AY) -> 0 | K6: =LOOKUP(Results!$D6,'Raw Data'!BA:BA,'Raw Data'!AW:AW) -> 0 | L6: ='Raw Data'!G7 -> 188908.94 | M6: =H6*L6/1000000 -> 7.6296129 | N6: =M6*AK6*96485/0.082057/298 -> 0 | O6: =N6/60 -> 0 | P6: =-O6*100/E6 -> 0 | Q6: ='Raw Data'!L7 -> 0 | R6: =Q6*H6/1000000 -> 0 | S6: =R6*AL6*96485/0.082057/298 -> 0 | T6: =S6/60 -> 0 | U6: =ABS(-T6*100/E6) -> 0 | V6: ='Raw Data'!Q7 -> 10431.079 | W6: =H6*V6/1000000 -> 0.42128815 | X6: =W6*AM6*96485/0.082057/298 -> 13298.331 | Y6: =X6/60 -> 221.63885 | Z6: =ABS(-Y6*100/E6) -> 27.702033 | AA6: ='Raw Data'!AE7 -> 52474.299 | AB6: =AA6*H6/1000000 -> 2.1193205 | AC6: =AB6*AN6*96485/0.082057/298 -> 16724.554 | AD6: =AC6/60 -> 278.74256 | AE6: =ABS(-AD6*100/E6) -> 34.83927 | AF6: =SUM(AE6+Z6+U6) -> 62.541303 | AJ6: ='Experimental details'!B21 -> CO | AK6: =IF(AJ6="CO",0,2) -> 0 | AL6: =IF(AJ6="CO",6,8) -> 6 | AM6: =IF(AJ6="CO",8,12) -> 8 | AN6: 2
A7: ='Raw Data'!A8 -> 251217_FID06.CHR | B7: ='Raw Data'!B3 -> 46008 | C7: ='Raw Data'!C8 -> 0.5862963 | D7: =(HOUR(C7)*3600)+(MINUTE(C7)*60)+SECOND(C7) -> 50656 | E7: ='Raw Data'!BL10 -> 799.96004 | F7: ='Raw Data'!BM10 -> -2.7945951 | G7: ='Experimental details'!$B$26 -> 244522 | H7: =10*G7*('Experimental details'!$B$22+'Experimental details'!$B$25)/'Experimental details'!$B$25/'Raw Data'!AJ8 -> 42.018033 | I7: =LOOKUP(Results!$D7,'Raw Data'!BA:BA,'Raw Data'!AX:AX) -> 0 | J7: =LOOKUP(Results!$D7,'Raw Data'!BA:BA,'Raw Data'!AY:AY) -> 0 | K7: =LOOKUP(Results!$D7,'Raw Data'!BA:BA,'Raw Data'!AW:AW) -> 0 | L7: ='Raw Data'!G8 -> 186486.49 | M7: =H7*L7/1000000 -> 7.8357955 | N7: =M7*AK7*96485/0.082057/298 -> 0 | O7: =N7/60 -> 0 | P7: =-O7*100/E7 -> 0 | Q7: ='Raw Data'!L8 -> 0 | R7: =Q7*H7/1000000 -> 0 | S7: =R7*AL7*96485/0.082057/298 -> 0 | T7: =S7/60 -> 0 | U7: =ABS(-T7*100/E7) -> 0 | V7: ='Raw Data'!Q8 -> 7155.3316 | W7: =H7*V7/1000000 -> 0.30065296 | X7: =W7*AM7*96485/0.082057/298 -> 9490.375 | Y7: =X7/60 -> 158.17292 | Z7: =ABS(-Y7*100/E7) -> 19.772602 | AA7: ='Raw Data'!AE8 -> 74952.917 | AB7: =AA7*H7/1000000 -> 3.1493742 | AC7: =AB7*AN7*96485/0.082057/298 -> 24853.191 | AD7: =AC7/60 -> 414.21985 | AE7: =ABS(-AD7*100/E7) -> 51.780068 | AF7: =SUM(AE7+Z7+U7) -> 71.55267 | AJ7: ='Experimental details'!B21 -> CO | AK7: =IF(AJ7="CO",0,2) -> 0 | AL7: =IF(AJ7="CO",6,8) -> 6 | AM7: =IF(AJ7="CO",8,12) -> 8 | AN7: 2
A8: ='Raw Data'!A9 -> 251217_FID07.CHR | B8: ='Raw Data'!B3 -> 46008 | C8: ='Raw Data'!C9 -> 0.5987963 | D8: =(HOUR(C8)*3600)+(MINUTE(C8)*60)+SECOND(C8) -> 51736 | E8: ='Raw Data'!BL11 -> 800.03657 | F8: ='Raw Data'!BM11 -> -2.4649581 | G8: ='Experimental details'!$B$26 -> 244522 | H8: =10*G8*('Experimental details'!$B$22+'Experimental details'!$B$25)/'Experimental details'!$B$25/'Raw Data'!AJ9 -> 43.783418 | I8: =LOOKUP(Results!$D8,'Raw Data'!BA:BA,'Raw Data'!AX:AX) -> 0 | J8: =LOOKUP(Results!$D8,'Raw Data'!BA:BA,'Raw Data'!AY:AY) -> 0 | K8: =LOOKUP(Results!$D8,'Raw Data'!BA:BA,'Raw Data'!AW:AW) -> 0 | L8: ='Raw Data'!G9 -> 183988.52 | M8: =H8*L8/1000000 -> 8.0556463 | N8: =M8*AK8*96485/0.082057/298 -> 0 | O8: =N8/60 -> 0 | P8: =-O8*100/E8 -> 0 | Q8: ='Raw Data'!L9 -> 0 | R8: =Q8*H8/1000000 -> 0 | S8: =R8*AL8*96485/0.082057/298 -> 0 | T8: =S8/60 -> 0 | U8: =ABS(-T8*100/E8) -> 0 | V8: ='Raw Data'!Q9 -> 3084.5789 | W8: =H8*V8/1000000 -> 0.13505341 | X8: =W8*AM8*96485/0.082057/298 -> 4263.0796 | Y8: =X8/60 -> 71.051326 | Z8: =ABS(-Y8*100/E8) -> 8.8810098 | AA8: ='Raw Data'!AE9 -> 96507.929 | AB8: =AA8*H8/1000000 -> 4.225447 | AC8: =AB8*AN8*96485/0.082057/298 -> 33344.987 | AD8: =AC8/60 -> 555.74979 | AE8: =ABS(-AD8*100/E8) -> 69.465548 | AF8: =SUM(AE8+Z8+U8) -> 78.346558 | AJ8: ='Experimental details'!B21 -> CO | AK8: =IF(AJ8="CO",0,2) -> 0 | AL8: =IF(AJ8="CO",6,8) -> 6 | AM8: =IF(AJ8="CO",8,12) -> 8 | AN8: 2
A9: ='Raw Data'!A10 -> 0 | B9: ='Raw Data'!B3 -> 46008 | C9: ='Raw Data'!C10 -> 0 | D9: =(HOUR(C9)*3600)+(MINUTE(C9)*60)+SECOND(C9) -> 0 | E9: ='Raw Data'!BL12 -> #N/A | F9: ='Raw Data'!BM12 -> #N/A | G9: ='Experimental details'!$B$26 -> 244522 | H9: =10*G9*('Experimental details'!$B$22+'Experimental details'!$B$25)/'Experimental details'!$B$25/'Raw Data'!AJ10 -> #DIV/0! | I9: =LOOKUP(Results!$D9,'Raw Data'!BA:BA,'Raw Data'!AX:AX) -> 0 | J9: =LOOKUP(Results!$D9,'Raw Data'!BA:BA,'Raw Data'!AY:AY) -> 0 | K9: =LOOKUP(Results!$D9,'Raw Data'!BA:BA,'Raw Data'!AW:AW) -> 0 | L9: ='Raw Data'!G10 -> 0 | M9: =H9*L9/1000000 -> #DIV/0! | N9: =M9*AK9*96485/0.082057/298 -> #DIV/0! | O9: =N9/60 -> #DIV/0! | P9: =-O9*100/E9 -> #DIV/0! | Q9: ='Raw Data'!L10 -> 0 | R9: =Q9*H9/1000000 -> #DIV/0! | S9: =R9*AL9*96485/0.082057/298 -> #DIV/0! | T9: =S9/60 -> #DIV/0! | U9: =ABS(-T9*100/E9) -> #DIV/0! | V9: ='Raw Data'!Q10 -> 0 | W9: =H9*V9/1000000 -> #DIV/0! | X9: =W9*AM9*96485/0.082057/298 -> #DIV/0! | Y9: =X9/60 -> #DIV/0! | Z9: =ABS(-Y9*100/E9) -> #DIV/0! | AA9: ='Raw Data'!AE10 -> 0 | AB9: =AA9*H9/1000000 -> #DIV/0! | AC9: =AB9*AN9*96485/0.082057/298 -> #DIV/0! | AD9: =AC9/60 -> #DIV/0! | AE9: =ABS(-AD9*100/E9) -> #DIV/0! | AF9: =SUM(AE9+Z9+U9) -> #DIV/0! | AJ9: ='Experimental details'!B21 -> CO | AK9: =IF(AJ9="CO",0,2) -> 0 | AL9: =IF(AJ9="CO",6,8) -> 6 | AM9: =IF(AJ9="CO",8,12) -> 8 | AN9: 2
A10: ='Raw Data'!A11 -> 0 | B10: ='Raw Data'!B3 -> 46008 | C10: ='Raw Data'!C11 -> 0 | D10: =(HOUR(C10)*3600)+(MINUTE(C10)*60)+SECOND(C10) -> 0 | E10: ='Raw Data'!BL13 -> #N/A | F10: ='Raw Data'!BM13 -> #N/A | G10: ='Experimental details'!$B$26 -> 244522 | H10: =10*G10*('Experimental details'!$B$22+'Experimental details'!$B$25)/'Experimental details'!$B$25/'Raw Data'!AJ11 -> #DIV/0! | I10: =LOOKUP(Results!$D10,'Raw Data'!BA:BA,'Raw Data'!AX:AX) -> 0 | J10: =LOOKUP(Results!$D10,'Raw Data'!BA:BA,'Raw Data'!AY:AY) -> 0 | K10: =LOOKUP(Results!$D10,'Raw Data'!BA:BA,'Raw Data'!AW:AW) -> 0 | L10: ='Raw Data'!G11 -> 0 | M10: =H10*L10/1000000 -> #DIV/0! | N10: =M10*AK10*96485/0.082057/298 -> #DIV/0! | O10: =N10/60 -> #DIV/0! | P10: =-O10*100/E10 -> #DIV/0! | Q10: ='Raw Data'!L11 -> 0 | R10: =Q10*H10/1000000 -> #DIV/0! | S10: =R10*AL10*96485/0.082057/298 -> #DIV/0! | T10: =S10/60 -> #DIV/0! | U10: =ABS(-T10*100/E10) -> #DIV/0! | V10: ='Raw Data'!Q11 -> 0 | W10: =H10*V10/1000000 -> #DIV/0! | X10: =W10*AM10*96485/0.082057/298 -> #DIV/0! | Y10: =X10/60 -> #DIV/0! | Z10: =ABS(-Y10*100/E10) -> #DIV/0! | AA10: ='Raw Data'!AE11 -> 0 | AB10: =AA10*H10/1000000 -> #DIV/0! | AC10: =AB10*AN10*96485/0.082057/298 -> #DIV/0! | AD10: =AC10/60 -> #DIV/0! | AE10: =ABS(-AD10*100/E10) -> #DIV/0! | AF10: =SUM(AE10+Z10+U10) -> #DIV/0! | AJ10: ='Experimental details'!B21 -> CO | AK10: =IF(AJ10="CO",0,2) -> 0 | AL10: =IF(AJ10="CO",6,8) -> 6 | AM10: =IF(AJ10="CO",8,12) -> 8 | AN10: 2
A11: ='Raw Data'!A12 -> 0 | B11: ='Raw Data'!B3 -> 46008 | C11: ='Raw Data'!C12 -> 0 | D11: =(HOUR(C11)*3600)+(MINUTE(C11)*60)+SECOND(C11) -> 0 | E11: ='Raw Data'!BL14 -> #N/A | F11: ='Raw Data'!BM14 -> #N/A | G11: ='Experimental details'!$B$26 -> 244522 | H11: =10*G11*('Experimental details'!$B$22+'Experimental details'!$B$25)/'Experimental details'!$B$25/'Raw Data'!AJ12 -> #DIV/0! | I11: =LOOKUP(Results!$D11,'Raw Data'!BA:BA,'Raw Data'!AX:AX) -> 0 | J11: =LOOKUP(Results!$D11,'Raw Data'!BA:BA,'Raw Data'!AY:AY) -> 0 | K11: =LOOKUP(Results!$D11,'Raw Data'!BA:BA,'Raw Data'!AW:AW) -> 0 | L11: ='Raw Data'!G12 -> 0 | M11: =H11*L11/1000000 -> #DIV/0! | N11: =M11*AK11*96485/0.082057/298 -> #DIV/0! | O11: =N11/60 -> #DIV/0! | P11: =-O11*100/E11 -> #DIV/0! | Q11: ='Raw Data'!L12 -> 0 | R11: =Q11*H11/1000000 -> #DIV/0! | S11: =R11*AL11*96485/0.082057/298 -> #DIV/0! | T11: =S11/60 -> #DIV/0! | U11: =ABS(-T11*100/E11) -> #DIV/0! | V11: ='Raw Data'!Q12 -> 0 | W11: =H11*V11/1000000 -> #DIV/0! | X11: =W11*AM11*96485/0.082057/298 -> #DIV/0! | Y11: =X11/60 -> #DIV/0! | Z11: =ABS(-Y11*100/E11) -> #DIV/0! | AA11: ='Raw Data'!AE12 -> 0 | AB11: =AA11*H11/1000000 -> #DIV/0! | AC11: =AB11*AN11*96485/0.082057/298 -> #DIV/0! | AD11: =AC11/60 -> #DIV/0! | AE11: =ABS(-AD11*100/E11) -> #DIV/0! | AF11: =SUM(AE11+Z11+U11) -> #DIV/0! | AJ11: ='Experimental details'!B21 -> CO | AK11: =IF(AJ11="CO",0,2) -> 0 | AL11: =IF(AJ11="CO",6,8) -> 6 | AM11: =IF(AJ11="CO",8,12) -> 8 | AN11: 2
A12: ='Raw Data'!A13 -> 0 | B12: ='Raw Data'!B3 -> 46008 | C12: ='Raw Data'!C13 -> 0 | D12: =(HOUR(C12)*3600)+(MINUTE(C12)*60)+SECOND(C12) -> 0 | E12: ='Raw Data'!BL15 -> #N/A | F12: ='Raw Data'!BM15 -> #N/A | G12: ='Experimental details'!$B$26 -> 244522 | H12: =10*G12*('Experimental details'!$B$22+'Experimental details'!$B$25)/'Experimental details'!$B$25/'Raw Data'!AJ13 -> #DIV/0! | I12: =LOOKUP(Results!$D12,'Raw Data'!BA:BA,'Raw Data'!AX:AX) -> 0 | J12: =LOOKUP(Results!$D12,'Raw Data'!BA:BA,'Raw Data'!AY:AY) -> 0 | K12: =LOOKUP(Results!$D12,'Raw Data'!BA:BA,'Raw Data'!AW:AW) -> 0 | L12: ='Raw Data'!G13 -> 0 | M12: =H12*L12/1000000 -> #DIV/0! | N12: =M12*AK12*96485/0.082057/298 -> #DIV/0! | O12: =N12/60 -> #DIV/0! | P12: =-O12*100/E12 -> #DIV/0! | Q12: ='Raw Data'!L13 -> 0 | R12: =Q12*H12/1000000 -> #DIV/0! | S12: =R12*AL12*96485/0.082057/298 -> #DIV/0! | T12: =S12/60 -> #DIV/0! | U12: =ABS(-T12*100/E12) -> #DIV/0! | V12: ='Raw Data'!Q13 -> 0 | W12: =H12*V12/1000000 -> #DIV/0! | X12: =W12*AM12*96485/0.082057/298 -> #DIV/0! | Y12: =X12/60 -> #DIV/0! | Z12: =ABS(-Y12*100/E12) -> #DIV/0! | AA12: ='Raw Data'!AE13 -> 0 | AB12: =AA12*H12/1000000 -> #DIV/0! | AC12: =AB12*AN12*96485/0.082057/298 -> #DIV/0! | AD12: =AC12/60 -> #DIV/0! | AE12: =ABS(-AD12*100/E12) -> #DIV/0! | AF12: =SUM(AE12+Z12+U12) -> #DIV/0! | AJ12: ='Experimental details'!B21 -> CO | AK12: =IF(AJ12="CO",0,2) -> 0 | AL12: =IF(AJ12="CO",6,8) -> 6 | AM12: =IF(AJ12="CO",8,12) -> 8 | AN12: 2
A13: ='Raw Data'!A14 -> 0 | B13: ='Raw Data'!B3 -> 46008 | C13: ='Raw Data'!C14 -> 0 | D13: =(HOUR(C13)*3600)+(MINUTE(C13)*60)+SECOND(C13) -> 0 | E13: ='Raw Data'!BL16 -> #N/A | F13: ='Raw Data'!BM16 -> #N/A | G13: ='Experimental details'!$B$26 -> 244522 | H13: =10*G13*('Experimental details'!$B$22+'Experimental details'!$B$25)/'Experimental details'!$B$25/'Raw Data'!AJ14 -> #DIV/0! | I13: =LOOKUP(Results!$D13,'Raw Data'!BA:BA,'Raw Data'!AX:AX) -> 0 | J13: =LOOKUP(Results!$D13,'Raw Data'!BA:BA,'Raw Data'!AY:AY) -> 0 | K13: =LOOKUP(Results!$D13,'Raw Data'!BA:BA,'Raw Data'!AW:AW) -> 0 | L13: ='Raw Data'!G14 -> 0 | M13: =H13*L13/1000000 -> #DIV/0! | N13: =M13*AK13*96485/0.082057/298 -> #DIV/0! | O13: =N13/60 -> #DIV/0! | P13: =-O13*100/E13 -> #DIV/0! | Q13: ='Raw Data'!L14 -> 0 | R13: =Q13*H13/1000000 -> #DIV/0! | S13: =R13*AL13*96485/0.082057/298 -> #DIV/0! | T13: =S13/60 -> #DIV/0! | U13: =ABS(-T13*100/E13) -> #DIV/0! | V13: ='Raw Data'!Q14 -> 0 | W13: =H13*V13/1000000 -> #DIV/0! | X13: =W13*AM13*96485/0.082057/298 -> #DIV/0! | Y13: =X13/60 -> #DIV/0! | Z13: =ABS(-Y13*100/E13) -> #DIV/0! | AA13: ='Raw Data'!AE14 -> 0 | AB13: =AA13*H13/1000000 -> #DIV/0! | AC13: =AB13*AN13*96485/0.082057/298 -> #DIV/0! | AD13: =AC13/60 -> #DIV/0! | AE13: =ABS(-AD13*100/E13) -> #DIV/0! | AF13: =SUM(AE13+Z13+U13) -> #DIV/0! | AJ13: ='Experimental details'!B21 -> CO | AK13: =IF(AJ13="CO",0,2) -> 0 | AL13: =IF(AJ13="CO",6,8) -> 6 | AM13: =IF(AJ13="CO",8,12) -> 8 | AN13: 2
A14: ='Raw Data'!A15 -> 0 | B14: ='Raw Data'!B3 -> 46008 | C14: ='Raw Data'!C15 -> 0 | D14: =(HOUR(C14)*3600)+(MINUTE(C14)*60)+SECOND(C14) -> 0 | E14: ='Raw Data'!BL17 -> #N/A | F14: ='Raw Data'!BM17 -> #N/A | G14: ='Experimental details'!$B$26 -> 244522 | H14: =10*G14*('Experimental details'!$B$22+'Experimental details'!$B$25)/'Experimental details'!$B$25/'Raw Data'!AJ15 -> #DIV/0! | I14: =LOOKUP(Results!$D14,'Raw Data'!BA:BA,'Raw Data'!AX:AX) -> 0 | J14: =LOOKUP(Results!$D14,'Raw Data'!BA:BA,'Raw Data'!AY:AY) -> 0 | K14: =LOOKUP(Results!$D14,'Raw Data'!BA:BA,'Raw Data'!AW:AW) -> 0 | L14: ='Raw Data'!G15 -> 0 | M14: =H14*L14/1000000 -> #DIV/0! | N14: =M14*AK14*96485/0.082057/298 -> #DIV/0! | O14: =N14/60 -> #DIV/0! | P14: =-O14*100/E14 -> #DIV/0! | Q14: ='Raw Data'!L15 -> 0 | R14: =Q14*H14/1000000 -> #DIV/0! | S14: =R14*AL14*96485/0.082057/298 -> #DIV/0! | T14: =S14/60 -> #DIV/0! | U14: =ABS(-T14*100/E14) -> #DIV/0! | V14: ='Raw Data'!Q15 -> 0 | W14: =H14*V14/1000000 -> #DIV/0! | X14: =W14*AM14*96485/0.082057/298 -> #DIV/0! | Y14: =X14/60 -> #DIV/0! | Z14: =ABS(-Y14*100/E14) -> #DIV/0! | AA14: ='Raw Data'!AE15 -> 0 | AB14: =AA14*H14/1000000 -> #DIV/0! | AC14: =AB14*AN14*96485/0.082057/298 -> #DIV/0! | AD14: =AC14/60 -> #DIV/0! | AE14: =ABS(-AD14*100/E14) -> #DIV/0! | AF14: =SUM(AE14+Z14+U14) -> #DIV/0! | AJ14: ='Experimental details'!B21 -> CO | AK14: =IF(AJ14="CO",0,2) -> 0 | AL14: =IF(AJ14="CO",6,8) -> 6 | AM14: =IF(AJ14="CO",8,12) -> 8 | AN14: 2
A15: ='Raw Data'!A16 -> 0 | B15: ='Raw Data'!B3 -> 46008 | C15: ='Raw Data'!C16 -> 0 | D15: =(HOUR(C15)*3600)+(MINUTE(C15)*60)+SECOND(C15) -> 0 | E15: ='Raw Data'!BL18 -> #N/A | F15: ='Raw Data'!BM18 -> #N/A | G15: ='Experimental details'!$B$26 -> 244522 | H15: =10*G15*('Experimental details'!$B$22+'Experimental details'!$B$25)/'Experimental details'!$B$25/'Raw Data'!AJ16 -> #DIV/0! | I15: =LOOKUP(Results!$D15,'Raw Data'!BA:BA,'Raw Data'!AX:AX) -> 0 | J15: =LOOKUP(Results!$D15,'Raw Data'!BA:BA,'Raw Data'!AY:AY) -> 0 | K15: =LOOKUP(Results!$D15,'Raw Data'!BA:BA,'Raw Data'!AW:AW) -> 0 | L15: ='Raw Data'!G16 -> 0 | M15: =H15*L15/1000000 -> #DIV/0! | N15: =M15*AK15*96485/0.082057/298 -> #DIV/0! | O15: =N15/60 -> #DIV/0! | P15: =-O15*100/E15 -> #DIV/0! | Q15: ='Raw Data'!L16 -> 0 | R15: =Q15*H15/1000000 -> #DIV/0! | S15: =R15*AL15*96485/0.082057/298 -> #DIV/0! | T15: =S15/60 -> #DIV/0! | U15: =ABS(-T15*100/E15) -> #DIV/0! | V15: ='Raw Data'!Q16 -> 0 | W15: =H15*V15/1000000 -> #DIV/0! | X15: =W15*AM15*96485/0.082057/298 -> #DIV/0! | Y15: =X15/60 -> #DIV/0! | Z15: =ABS(-Y15*100/E15) -> #DIV/0! | AA15: ='Raw Data'!AE16 -> 0 | AB15: =AA15*H15/1000000 -> #DIV/0! | AC15: =AB15*AN15*96485/0.082057/298 -> #DIV/0! | AD15: =AC15/60 -> #DIV/0! | AE15: =ABS(-AD15*100/E15) -> #DIV/0! | AF15: =SUM(AE15+Z15+U15) -> #DIV/0! | AJ15: ='Experimental details'!B21 -> CO | AK15: =IF(AJ15="CO",0,2) -> 0 | AL15: =IF(AJ15="CO",6,8) -> 6 | AM15: =IF(AJ15="CO",8,12) -> 8 | AN15: 2

Sheet Recipe Mappings
B1: AR_Ir_SD_0001 | C1: AR_Ir_SD_0002 | H1: CR_Cu_SD_0001 | I1: CR_Cu_SD_0002 | J1: CR_Cu_SD_0003 | K1: CR_Cu_UN_0001 | L1: CR_Ag_SD_0001
A2: Recipe Name | B2: Ir | C2: Ir on Titanium | H2: Cu 9% Nafion | I2: Cu 0% Nafion | J2: Cu 1xNafion | K2: Cu spray nozzle | L2: Silver
A3: Element | B3: Ir | C3: Ir | H3: Cu | I3: Cu | J3: Cu | K3: Cu | L3: Ag
A4: Element Mass (mg) | B4: 190 | C4: 190 | H4: 200 | I4: 200 | J4: 200 | K4: 200
A5: Solvent 1 Type | B5: Isopropanol | C5: H20 | H5: Isopropanol | I5: Isopropanol | J5: Isopropanol | K5: Isopropanol | L5: Isopropanol
A6: Solvent 1 Volume (ml) | B6: 10 | C6: 4.75 | H6: 10 | I6: 10 | J6: 10 | K6: 20 | L6: 20
A7: Solvent 2 Type | B7: H2O | C7: Isopropanol | H7: H2O | I7: H2O | J7: H2O | K7: H2O | L7: H2O
A8: Solvent 2 Volume (ml) | B8: 0 | C8: 4.75 | H8: 10 | I8: 10 | J8: 10 | K8: 20 | L8: 20
A9: Ionomer 1 Type | B9: Sustanion XA-9 5% in Ethanol | C9: Sustanion XA-9 5% in Ethanol | H9: Nafion perfluorinated resin solution | J9: Nafion perfluorinated resin solution | K9: Sustanion | L9: PTFE
A10: Ionomer 1 Mass (mg) | B10: 670 | C10: 670 | H10: 420 | J10: 600 | K10: 20 | L10: 20
A11: Ionomer 2 Type | L11: Sustanion XA-9 5% in Ethanol
A12: Ionomer 2 Mass (mg) | L12: 30
A13: Deposition Method | B13: Spray Dep | C13: Spray Dep | H13: Spray Dep | I13: Spray Dep | J13: Spray Dep | K13: Ultrasonic Nozzle | L13: Spray Dep
A14: Deposition Temperature (°C) | B14: 185 | C14: 180 | H14: 185 | I14: 185 | J14: 185 | K14: 185 | L14: 185
A15: N2 Deposition Pressure (bar) | B15: 2 | C15: 2 | H15: 2 | I15: 2 | J15: 2 | K15: 1.5 | L15: 2
A16: Substrate | B16: Platinum | C16: Titanium | H16: Freudenberg H23C6 | I16: Freudenberg H23C6 | J16: Freudenberg H23C6 | K16: GDL | L16: Freudenberg H23C6
A17: Substrate Dimension | B17: 6 frits | C17: frit | H17: 14 x 4 | I17: 14 x 4 | J17: 14 x 4 | K17: 250 micron | L17: 4 x 14
A18: Substrate Total Area (cm²) | B18: 48 | H18: 54 | I18: 54 | J18: 54 | K18: 8 | L18: 56
A19: Substrate Cleaning
A20: Mass Loading (mg/cm2) | H20: 1 | I20: 1 | J20: 1 | K20: 1 | L20: 1
A21: Recipe Remarks
